<?xml version="1.0" ?>
<sdf version="1.7">
  <world name="pulsar_mobile_robot_world">
    
    <!-- Physics configuration for real-time simulation -->
    <physics name="real_time_physics" type="ode">
      <max_step_size>0.001</max_step_size>
      <real_time_factor>1.0</real_time_factor>
      <real_time_update_rate>1000</real_time_update_rate>
      <ode>
        <solver>
          <type>quick</type>
          <iters>50</iters>
          <precon_iters>0</precon_iters>
          <sor>1.3</sor>
          <use_dynamic_moi_rescaling>false</use_dynamic_moi_rescaling>
        </solver>
        <constraints>
          <cfm>0.0</cfm>
          <erp>0.2</erp>
          <contact_max_correcting_vel>100.0</contact_max_correcting_vel>
          <contact_surface_layer>0.01</contact_surface_layer>
        </constraints>
      </ode>
    </physics>
    
    <!-- Lighting -->
    <include>
      <uri>model://sun</uri>
    </include>
    
    <!-- Ground plane -->
    <include>
      <uri>model://ground_plane</uri>
    </include>
    
    <!-- Factory environment -->
    <model name="factory_floor">
      <static>true</static>
      <link name="floor">
        <collision name="floor_collision">
          <geometry>
            <plane>
              <normal>0 0 1</normal>
              <size>50 50</size>
            </plane>
          </geometry>
          <surface>
            <friction>
              <ode>
                <mu>100</mu>
                <mu2>50</mu2>
              </ode>
            </friction>
          </surface>
        </collision>
        <visual name="floor_visual">
          <geometry>
            <plane>
              <normal>0 0 1</normal>
              <size>50 50</size>
            </plane>
          </geometry>
          <material>
            <script>
              <uri>file://media/materials/scripts/gazebo.material</uri>
              <name>Gazebo/Grey</name>
            </script>
          </material>
        </visual>
      </link>
    </model>
    
    <!-- Obstacles for navigation testing -->
    <model name="obstacle_1">
      <static>true</static>
      <pose>5 5 0.5 0 0 0</pose>
      <link name="link">
        <collision name="collision">
          <geometry>
            <box>
              <size>1 1 1</size>
            </box>
          </geometry>
        </collision>
        <visual name="visual">
          <geometry>
            <box>
              <size>1 1 1</size>
            </box>
          </geometry>
          <material>
            <script>
              <uri>file://media/materials/scripts/gazebo.material</uri>
              <name>Gazebo/Wood</name>
            </script>
          </material>
        </visual>
      </link>
    </model>
    
    <model name="obstacle_2">
      <static>true</static>
      <pose>-3 8 0.5 0 0 0</pose>
      <link name="link">
        <collision name="collision">
          <geometry>
            <cylinder>
              <radius>0.5</radius>
              <length>1</length>
            </cylinder>
          </geometry>
        </collision>
        <visual name="visual">
          <geometry>
            <cylinder>
              <radius>0.5</radius>
              <length>1</length>
            </cylinder>
          </geometry>
          <material>
            <script>
              <uri>file://media/materials/scripts/gazebo.material</uri>
              <name>Gazebo/Red</name>
            </script>
          </material>
        </visual>
      </link>
    </model>
    
    <!-- Real-time mobile robot with Pulsar integration -->
    <model name="pulsar_mobile_robot">
      <pose>0 0 0.1 0 0 0</pose>
      
      <!-- Base link -->
      <link name="base_link">
        <inertial>
          <mass>10.0</mass>
          <pose>0 0 0 0 0 0</pose>
          <inertia>
            <ixx>0.1</ixx>
            <ixy>0.0</ixy>
            <ixz>0.0</ixz>
            <iyy>0.1</iyy>
            <iyz>0.0</iyz>
            <izz>0.1</izz>
          </inertia>
        </inertial>
        
        <collision name="base_collision">
          <geometry>
            <box>
              <size>0.6 0.4 0.2</size>
            </box>
          </geometry>
        </collision>
        
        <visual name="base_visual">
          <geometry>
            <box>
              <size>0.6 0.4 0.2</size>
            </box>
          </geometry>
          <material>
            <script>
              <uri>file://media/materials/scripts/gazebo.material</uri>
              <name>Gazebo/Blue</name>
            </script>
          </material>
        </visual>
      </link>
      
      <!-- Left wheel -->
      <link name="left_wheel">
        <pose>0.15 0.25 0 1.5708 0 0</pose>
        <inertial>
          <mass>1.0</mass>
          <inertia>
            <ixx>0.005</ixx>
            <ixy>0.0</ixy>
            <ixz>0.0</ixz>
            <iyy>0.005</iyy>
            <iyz>0.0</iyz>
            <izz>0.01</izz>
          </inertia>
        </inertial>
        
        <collision name="left_wheel_collision">
          <geometry>
            <cylinder>
              <radius>0.1</radius>
              <length>0.05</length>
            </cylinder>
          </geometry>
          <surface>
            <friction>
              <ode>
                <mu>1.0</mu>
                <mu2>1.0</mu2>
                <slip1>0.0</slip1>
                <slip2>0.0</slip2>
              </ode>
            </friction>
          </surface>
        </collision>
        
        <visual name="left_wheel_visual">
          <geometry>
            <cylinder>
              <radius>0.1</radius>
              <length>0.05</length>
            </cylinder>
          </geometry>
          <material>
            <script>
              <uri>file://media/materials/scripts/gazebo.material</uri>
              <name>Gazebo/Black</name>
            </script>
          </material>
        </visual>
      </link>
      
      <!-- Right wheel -->
      <link name="right_wheel">
        <pose>0.15 -0.25 0 1.5708 0 0</pose>
        <inertial>
          <mass>1.0</mass>
          <inertia>
            <ixx>0.005</ixx>
            <ixy>0.0</ixy>
            <ixz>0.0</ixz>
            <iyy>0.005</iyy>
            <iyz>0.0</iyyz>
            <izz>0.01</izz>
          </inertia>
        </inertial>
        
        <collision name="right_wheel_collision">
          <geometry>
            <cylinder>
              <radius>0.1</radius>
              <length>0.05</length>
            </cylinder>
          </geometry>
          <surface>
            <friction>
              <ode>
                <mu>1.0</mu>
                <mu2>1.0</mu2>
                <slip1>0.0</slip1>
                <slip2>0.0</slip2>
              </ode>
            </friction>
          </surface>
        </collision>
        
        <visual name="right_wheel_visual">
          <geometry>
            <cylinder>
              <radius>0.1</radius>
              <length>0.05</length>
            </cylinder>
          </geometry>
          <material>
            <script>
              <uri>file://media/materials/scripts/gazebo.material</uri>
              <name>Gazebo/Black</name>
            </script>
          </material>
        </visual>
      </link>
      
      <!-- Caster wheel -->
      <link name="caster_wheel">
        <pose>-0.2 0 -0.05 0 0 0</pose>
        <inertial>
          <mass>0.1</mass>
          <inertia>
            <ixx>0.001</ixx>
            <ixy>0.0</ixy>
            <ixz>0.0</ixz>
            <iyy>0.001</iyy>
            <iyz>0.0</iyz>
            <izz>0.001</izz>
          </inertia>
        </inertial>
        
        <collision name="caster_collision">
          <geometry>
            <sphere>
              <radius>0.05</radius>
            </sphere>
          </geometry>
          <surface>
            <friction>
              <ode>
                <mu>0.0</mu>
                <mu2>0.0</mu2>
                <slip1>1.0</slip1>
                <slip2>1.0</slip2>
              </ode>
            </friction>
          </surface>
        </collision>
        
        <visual name="caster_visual">
          <geometry>
            <sphere>
              <radius>0.05</radius>
            </sphere>
          </geometry>
          <material>
            <script>
              <uri>file://media/materials/scripts/gazebo.material</uri>
              <name>Gazebo/Grey</name>
            </script>
          </material>
        </visual>
      </link>
      
      <!-- LiDAR sensor -->
      <link name="lidar_link">
        <pose>0 0 0.2 0 0 0</pose>
        <inertial>
          <mass>0.1</mass>
          <inertia>
            <ixx>0.001</ixx>
            <ixy>0.0</ixy>
            <ixz>0.0</ixz>
            <iyy>0.001</iyy>
            <iyz>0.0</iyz>
            <izz>0.001</izz>
          </inertia>
        </inertial>
        
        <collision name="lidar_collision">
          <geometry>
            <cylinder>
              <radius>0.05</radius>
              <length>0.1</length>
            </cylinder>
          </geometry>
        </collision>
        
        <visual name="lidar_visual">
          <geometry>
            <cylinder>
              <radius>0.05</radius>
              <length>0.1</length>
            </cylinder>
          </geometry>
          <material>
            <script>
              <uri>file://media/materials/scripts/gazebo.material</uri>
              <name>Gazebo/Green</name>
            </script>
          </material>
        </visual>
        
        <sensor name="lidar" type="ray">
          <pose>0 0 0 0 0 0</pose>
          <visualize>true</visualize>
          <update_rate>20</update_rate>
          <ray>
            <scan>
              <horizontal>
                <samples>360</samples>
                <resolution>1</resolution>
                <min_angle>-3.14159</min_angle>
                <max_angle>3.14159</max_angle>
              </horizontal>
            </scan>
            <range>
              <min>0.1</min>
              <max>10.0</max>
              <resolution>0.01</resolution>
            </range>
            <noise>
              <type>gaussian</type>
              <mean>0.0</mean>
              <stddev>0.01</stddev>
            </noise>
          </ray>
          <plugin name="gazebo_ros_laser" filename="libgazebo_ros_laser.so">
            <topicName>/scan</topicName>
            <frameName>lidar_link</frameName>
          </plugin>
        </sensor>
      </link>
      
      <!-- IMU sensor -->
      <link name="imu_link">
        <pose>0 0 0.1 0 0 0</pose>
        <inertial>
          <mass>0.01</mass>
          <inertia>
            <ixx>0.0001</ixx>
            <ixy>0.0</ixy>
            <ixz>0.0</ixz>
            <iyy>0.0001</iyy>
            <iyz>0.0</iyz>
            <izz>0.0001</izz>
          </inertia>
        </inertial>
        
        <sensor name="imu" type="imu">
          <always_on>true</always_on>
          <update_rate>100</update_rate>
          <plugin name="gazebo_ros_imu" filename="libgazebo_ros_imu.so">
            <topicName>/imu</topicName>
            <bodyName>imu_link</bodyName>
            <updateRateHZ>100.0</updateRateHZ>
            <gaussianNoise>0.01</gaussianNoise>
            <xyzOffset>0 0 0</xyzOffset>
            <rpyOffset>0 0 0</rpyOffset>
          </plugin>
        </sensor>
      </link>
      
      <!-- Joint connections -->
      <joint name="left_wheel_joint" type="revolute">
        <parent>base_link</parent>
        <child>left_wheel</child>
        <axis>
          <xyz>0 1 0</xyz>
        </axis>
      </joint>
      
      <joint name="right_wheel_joint" type="revolute">
        <parent>base_link</parent>
        <child>right_wheel</child>
        <axis>
          <xyz>0 1 0</xyz>
        </axis>
      </joint>
      
      <joint name="caster_joint" type="ball">
        <parent>base_link</parent>
        <child>caster_wheel</child>
      </joint>
      
      <joint name="lidar_joint" type="fixed">
        <parent>base_link</parent>
        <child>lidar_link</child>
      </joint>
      
      <joint name="imu_joint" type="fixed">
        <parent>base_link</parent>
        <child>imu_link</child>
      </joint>
      
      <!-- Differential drive plugin with real-time constraints -->
      <plugin name="differential_drive_controller" filename="libgazebo_ros_diff_drive.so">
        <alwaysOn>true</alwaysOn>
        <updateRate>100.0</updateRate>
        <leftJoint>left_wheel_joint</leftJoint>
        <rightJoint>right_wheel_joint</rightJoint>
        <wheelSeparation>0.5</wheelSeparation>
        <wheelDiameter>0.2</wheelDiameter>
        <torque>10</torque>
        <commandTopic>cmd_vel</commandTopic>
        <odometryTopic>odom</odometryTopic>
        <odometryFrame>odom</odometryFrame>
        <robotBaseFrame>base_link</robotBaseFrame>
        <publishWheelTF>true</publishWheelTF>
        <publishWheelJointState>true</publishWheelJointState>
        <wheelAcceleration>2.0</wheelAcceleration>
        <wheelTorque>10</wheelTorque>
        <rosDebugLevel>na</rosDebugLevel>
      </plugin>
    </model>
    
    <!-- GPS reference for localization -->
    <spherical_coordinates>
      <surface_model>EARTH_WGS84</surface_model>
      <latitude_deg>37.7749</latitude_deg>
      <longitude_deg>-122.4194</longitude_deg>
      <elevation>0</elevation>
      <heading_deg>0</heading_deg>
    </spherical_coordinates>
    
    <!-- Real-time GUI plugin -->
    <gui fullscreen='0'>
      <camera name='user_camera'>
        <pose>5.0 -5.0 3.0 0.0 0.4 2.4</pose>
        <view_controller>orbit</view_controller>
      </camera>
    </gui>
    
  </world>
</sdf>